Workbook

Sheet 系统属性
A1: 序号 | B1: 对象 | C1: 属性 | D1: 名称 | E1: 类型 | F1: 属性值 | G1: 所属分类 | H1: 备注
A2: 1 | B2: 零组件 | C2: EnterpriseExtension.V_PartNumber | D2: 零件号 | E2: 字符串 | G2: NA
A3: 2 | B3: 零组件 | C3: JF_VPMReference.JF_Detail_CN | D3: 详细类别-CN | E3: 字符串 | G3: NA
A4: 3 | B4: 零组件 | C4: JF_VPMReference.JF_Detail_EN | D4: 详细类别-EN | E4: 字符串 | G4: NA
A5: 4 | B5: 零组件 | C5: JF_VPMReference.JF_PartNameCN | D5: 零件中文名称 | E5: 字符串 | G5: NA
A6: 5 | B6: 零组件 | C6: JF_VPMReference.JF_PartNameEN | D6: 零件英文名称 | E6: 字符串 | G6: NA
A7: 6 | B7: 零组件 | C7: JF_VPMReference.PartType | D7: 零件类型 | E7: 字符串 | G7: NA
A8: 7 | B8: 零组件 | C8: JF_VPMReference.PartSubType | D8: 零件子类型 | E8: 字符串 | G8: NA
A9: 8 | B9: 零组件 | C9: JF_VPMReference.JF_ProcurementType | D9: 零件采购类型 | E9: 字符串 | G9: NA
A10: 9 | B10: 零组件 | C10: JF_VPMReference.JF_DirectBuy | D10: DirectBuy | E10: 字符串 | G10: NA
A11: 10 | B11: 零组件 | C11: JF_VPMReference.Weight | D11: 参考重量 | E11: 字符串 | G11: NA
A12: 11 | B12: 零组件 | C12: JF_VPMReference.JF_WeightTarget | D12: 实际重量 | E12: 字符串 | G12: NA
A13: 12 | B13: 零组件 | C13: JF_VPMReference.JF_Unit | D13: 单位 | E13: 字符串 | G13: NA
... A157: 156 | B157: 零组件BOM | C157: JF_VPMInstance.JF_Symmetry | D157: 对称 | E157: 字符串 | G157: NA

Sheet CostingLogical
A1: 序号 | B1: 对象类型 | C1: 名称 | D1: 属性 | E1: 名称 | F1: 类型 | G1: 参数类型 | H1: 值 | I1: 备注
A2: 1 | B2: 成本分析 | C2: 面套成本核算 | D2: JF Fabric Material Unit Price | E2: 面料单价 | F2: 实数 | G2: 输入
A3: 2 | B3: 零组件 | C3: 面套成本核算 | D3: NetArea | E3: 净面积(m2) | F3: 实数 | G3: 公式 | H3: =系统属性!F47 -> 0
A4: 3 | B4: 成本分析 | C4: 面套成本核算 | D4: JF Utilization | E4: 利用率 | F4: 实数 | G4: 输入
A5: 4 | B5: 成本分析 | C5: 面套成本核算 | D5: JF Fabric Cost | E5: 面料价格 | F5: 实数 | G5: 公式 | H5: =IFERROR(H2*H3/H4,0) -> 0
A6: 5 | B6: 成本分析 | C6: 面套成本核算 | D6: JF Foam Unit Price | E6: 海绵单价 | F6: 实数 | G6: 输入
A7: 6 | B7: 成本分析 | C7: 面套成本核算 | D7: JF Foam Cost | E7: 海绵价格 | F7: 实数 | G7: 公式 | H7: =IFERROR(H6*H3/H4,0) -> 0
A8: 7 | B8: 成本分析 | C8: 面套成本核算 | D8: JF Backing Unit Price | E8: 底布单价 | F8: 实数 | G8: 输入
A9: 8 | B9: 成本分析 | C9: 面套成本核算 | D9: JF Backing Cost | E9: 底布价格 | F9: 实数 | G9: 公式 | H9: =IFERROR(H8*H3/H4,0) -> 0
A10: 9 | B10: 成本分析 | C10: 面套成本核算 | D10: JF Retainer Unit Price | E10: 型条单价 | F10: 实数 | G10: 输入
A11: 10 | B11: 成本分析 | C11: 面套成本核算 | D11: JF Retainer Cost | E11: 型条价格 | F11: 实数 | G11: 公式 | H11: =H10*H12/1000 -> 0
A12: 11 | B12: 零组件 | C12: 面套成本核算 | D12: JFLength | E12: 长(mm) | F12: 实数 | G12: 公式 | H12: =系统属性!F29 -> 0
A13: 12 | B13: 成本分析 | C13: 面套成本核算 | D13: JF Piping Unit Price | E13: 绲边单价 | F13: 实数 | G13: 输入
A14: 13 | B14: 成本分析 | C14: 面套成本核算 | D14: JF Piping Cost | E14: 绲边价格 | F14: 实数 | G14: 公式 | H14: =H13*H12/1000 -> 0
A15: 14 | B15: 成本分析 | C15: 面套成本核算 | D15: JF Elastic Unit Price | E15: 松紧带单价 | F15: 实数 | G15: 输入
A16: 15 | B16: 成本分析 | C16: 面套成本核算 | D16: JF Elastic Cost | E16: 松紧带价格 | F16: 实数 | G16: 公式 | H16: =H15*H12/1000 -> 0
A17: 16 | B17: 成本分析 | C17: 面套成本核算 | D17: JF Strap Assy Unit Price | E17: 织物拉带单价 | F17: 实数 | G17: 输入
A18: 17 | B18: 成本分析 | C18: 面套成本核算 | D18: JF Strap Assy Cost | E18: 织物拉带价格 | F18: 实数 | G18: 公式 | H18: =H17*H12/1000 -> 0
A19: 18 | B19: 成本分析 | C19: 面套成本核算 | D19: JF Thread Unit Price | E19: 缝线单价 | F19: 实数 | G19: 输入
A20: 19 | B20: 成本分析 | C20: 面套成本核算 | D20: JF Thread Cost | E20: 缝线价格 | F20: 实数 | G20: 公式 | H20: =H19*H12/1000 -> 0
A21: 20 | B21: 零组件BOM | C21: 面套成本核算 | D21: JF_VPMInstance.JF_Dosage | E21: 用量 | F21: 实数 | G21: 公式 | H21: =系统属性!F153 -> 0
A22: 21 | B22: 成本分析 | C22: 面套成本核算 | D22: JF Zipper Unit Price | E22: 拉链单价 | F22: 实数 | G22: 输入
A23: 22 | B23: 成本分析 | C23: 面套成本核算 | D23: JF Zipper Cost | E23: 拉链价格 | F23: 实数 | G23: 公式 | H23: =H22*H21 -> 0
A24: 23 | B24: 成本分析 | C24: 面套成本核算 | D24: JF Label Unit Price | E24: 标签单价 | F24: 实数 | G24: 输入
A25: 24 | B25: 成本分析 | C25: 面套成本核算 | D25: JF Label Cost | E25: 标签价格 | F25: 实数 | G25: 公式 | H25: =H24*H21 -> 0
A26: 25 | B26: 成本分析 | C26: 面套成本核算 | D26: JF Material Cost | E26: 材料费 | F26: 实数 | G26: 公式 | H26: =IFERROR(H5+H7+H9+H11+H14+H16+H18+H20+H23+H25,0) -> 0
A27: 26 | B27: 零组件 | C27: 面套成本核算 | D27: JF_VPMReference.JF_ProcurementType | E27: 零件采购类型 | F27: 字符串 | G27: 公式 | H27: =系统属性!F9 -> 0
A28: 27 | B28: 成本分析 | C28: 面套成本核算 | D28: JF Fabric Material Type | E28: 是否真皮 | F28: 字符串 | G28: 输入 | H28: N
A29: 28 | B29: 零组件 | C29: 面套成本核算 | D29: Circumference | E29: 周长(mm) | F29: 实数 | G29: 公式 | H29: =系统属性!F49 -> 0
A30: 29 | B30: 成本分析 | C30: 面套成本核算 | D30: JF Pattern Layer Quantity | E30: 裁片层数 | F30: 实数 | G30: 公式 | H30: =IF(H28="N",10,1) -> 10
A31: 30 | B31: 成本分析 | C31: 面套成本核算 | D31: JF Cutting Velocity | E31: 裁片速度（m/min) | F31: 实数 | G31: 公式 | H31: =IF(H28="N",3,2.2) -> 3
A32: 31 | B32: 成本分析 | C32: 面套成本核算 | D32: JF Fabric Material Cutting CT | E32: 裁剪面料CT | F32: 实数 | G32: 公式 | H32: =IFERROR(H29/1000/H30/H31,0) -> 0
A33: 32 | B33: 成本分析 | C33: 面套成本核算 | D33: JF Fabric Material Cutting Manufacturing Rate | E33: 裁剪面料费率 | F33: 实数 | G33: 公式 | H33: =IF(H28="N",2.3,3.1) -> 2.3
A34: 33 | B34: 成本分析 | C34: 面套成本核算 | D34: JF Fabric Material Cutting Cost | E34: 裁剪面料制费 | F34: 实数 | G34: 公式 | H34: =IF(H27="buy",H32*H33,0) -> 0
A35: 34 | B35: 零组件 | C35: 面套成本核算 | D35: PerforationQuantity | E35: 打孔数 | F35: 整数 | G35: 公式 | H35: =系统属性!F70 -> 0
A36: 35 | B36: 成本分析 | C36: 面套成本核算 | D36: JF Piercing Velocity | E36: 设备打孔速度 (孔/min） | F36: 实数 | G36: 公式 | H36: =1200 -> 1200
A37: 36 | B37: 成本分析 | C37: 面套成本核算 | D37: JF Piercing CT | E37: 打孔CT(Min) | F37: 实数 | G37: 公式 | H37: =IFERROR(H35/H36/2,0) -> 0
A38: 37 | B38: 成本分析 | C38: 面套成本核算 | D38: JF Piercing Manufacturing Rate | E38: 生产Rate /Min | F38: 实数 | G38: 公式 | H38: =0.88 -> 0.88
A39: 38 | B39: 成本分析 | C39: 面套成本核算 | D39: JF OEE | E39: OEE | F39: 实数 | G39: 公式 | H39: =0.85 -> 0.85
A40: 39 | B40: 成本分析 | C40: 面套成本核算 | D40: JF Scrap Rate | E40: Scrap | F40: 实数 | G40: 公式 | H40: =0.02 -> 0.02
...

Sheet 选项匹配
A1: A属性 | B1: B属性
A2: A | B2: A
A3: B | B3: C
A4: C | B4: E
